<?xml version="1.0" ?>
<sdf version="1.8">
  <model name='vehicle_blue' canonical_link='chassis'>
    <pose>0 0 0 0 0 0</pose>

    <link name='chassis'>
      <pose relative_to='__model__'>0.5 0 0.4 0 0 0</pose>
      <inertial> <mass>1.14395</mass> <inertia> <ixx>0.095329</ixx> <ixy>0</ixy> <ixz>0</ixz> <iyy>0.381317</iyy> <iyz>0</iyz> <izz>0.476646</izz> </inertia> </inertial>
      <visual name='visual'> <geometry> <box> <size>2.0 1.0 0.5</size> </box> </geometry> <material> <ambient>0.0 0.0 1.0 1</ambient> <diffuse>0.0 0.0 1.0 1</diffuse> <specular>0.0 0.0 1.0 1</specular> </material> </visual>
      <collision name='collision'> <geometry> <box> <size>2.0 1.0 0.5</size> </box> </geometry> </collision>
      
      <sensor name='camera_sensor' type='camera'>
        <pose>1.0 0 0.25 0 0 0</pose> 
        <camera>
          <horizontal_fov>1.047</horizontal_fov> 
          <image>
            <width>640</width>
            <height>480</height>
            <format>R8G8B8</format>
          </image>
          <clip>
            <near>0.1</near>
            <far>100</far>
          </clip>
        </camera>
        <update_rate>30</update_rate>
        <topic>/model/vehicle_blue/camera</topic> 
      </sensor>
    </link>

    <link name='left_wheel'>
      <pose relative_to="chassis">-0.5 0.6 0 -1.5707 0 0</pose>
      <inertial> <mass>1</mass> <inertia> <ixx>0.043333</ixx> <ixy>0</ixy> <ixz>0</ixz> <iyy>0.043333</iyy> <iyz>0</iyz> <izz>0.08</izz> </inertia> </inertial>
      <visual name='visual'> <geometry> <cylinder> <radius>0.4</radius> <length>0.2</length> </cylinder> </geometry> <material> <ambient>1.0 0.0 0.0 1</ambient> <diffuse>1.0 0.0 0.0 1</diffuse> <specular>1.0 0.0 0.0 1</specular> </material> </visual>
      <collision name='collision'> <geometry> <cylinder> <radius>0.4</radius> <length>0.2</length> </cylinder> </geometry> </collision>
    </link>

    <link name='right_wheel'>
      <pose relative_to="chassis">-0.5 -0.6 0 -1.5707 0 0</pose>
      <inertial> <mass>1</mass> <inertia> <ixx>0.043333</ixx> <ixy>0</ixy> <ixz>0</ixz> <iyy>0.043333</iyy> <iyz>0</iyz> <izz>0.08</izz> </inertia> </inertial>
      <visual name='visual'> <geometry> <cylinder> <radius>0.4</radius> <length>0.2</length> </cylinder> </geometry> <material> <ambient>1.0 0.0 0.0 1</ambient> <diffuse>1.0 0.0 0.0 1</diffuse> <specular>1.0 0.0 0.0 1</specular> </material> </visual>
      <collision name='collision'> <geometry> <cylinder> <radius>0.4</radius> <length>0.2</length> </cylinder> </geometry> </collision>
    </link>

    <frame name="caster_frame" attached_to='chassis'> <pose>0.8 0 -0.2 0 0 0</pose> </frame>
    <link name='caster'>
      <pose relative_to='caster_frame'/>
      <inertial> <mass>1</mass> <inertia> <ixx>0.016</ixx> <ixy>0</ixy> <ixz>0</ixz> <iyy>0.016</iyy> <iyz>0</iyz> <izz>0.016</izz> </inertia> </inertial>
      <visual name='visual'> <geometry> <sphere> <radius>0.2</radius> </sphere> </geometry> <material> <ambient>0.0 1 0.0 1</ambient> <diffuse>0.0 1 0.0 1</diffuse> <specular>0.0 1 0.0 1</specular> </material> </visual>
      <collision name='collision'> <geometry> <sphere> <radius>0.2</radius> </sphere> </geometry> </collision>
    </link>

    <joint name='left_wheel_joint' type='revolute'>
      <pose relative_to='left_wheel'/>
      <parent>chassis</parent>
      <child>left_wheel</child>
      <axis> <xyz expressed_in='__model__'>0 1 0</xyz> <limit> <lower>-1.79769e+308</lower> <upper>1.79769e+308</upper> </limit> </axis>
    </joint>
    <joint name='right_wheel_joint' type='revolute'>
      <pose relative_to='right_wheel'/>
      <parent>chassis</parent>
      <child>right_wheel</child>
      <axis> <xyz expressed_in='__model__'>0 1 0</xyz> <limit> <lower>-1.79769e+308</lower> <upper>1.79769e+308</upper> </limit> </axis>
    </joint>
    <joint name='caster_wheel' type='ball'>
      <parent>chassis</parent>
      <child>caster</child>
    </joint>

    <plugin
      filename="gz-sim-diff-drive-system"
      name="gz::sim::systems::DiffDrive">
      <left_joint>left_wheel_joint</left_joint>
      <right_joint>right_wheel_joint</right_joint>
      <wheel_separation>1.2</wheel_separation> <wheel_radius>0.4</wheel_radius>
    </plugin>

    <plugin
      filename="gz-sim-joint-state-publisher-system"
      name="gz::sim::systems::JointStatePublisher">
    </plugin>

    <plugin
      filename="gz-sim-pose-publisher-system"
      name="gz::sim::systems::PosePublisher">
      <publish_link_pose>true</publish_link_pose>
      <publish_sensor_pose>true</publish_sensor_pose>
      <publish_collision_pose>false</publish_collision_pose>
      <publish_visual_pose>false</publish_visual_pose>
      <publish_model_pose>true</publish_model_pose>
      <use_static_publisher>false</use_static_publisher>
    </plugin>
    
    <plugin
       filename="gz-sim-sensors-system"
       name="gz::sim::systems::Sensors">
    </plugin>

  </model>
</sdf>

